Workbook

Sheet Jan.
A1: Jan 2016 | K1: =IF(A1="","",A1) -> Jan 2016 | W1: =IF(A1="","",A1) -> Jan 2016 | AG1: =IF(A1="","",A1) -> Jan 2016 | AQ1: =IF(A1="","",A1) -> Jan 2016 | BA1: =IF(A1="","",A1) -> Jan 2016 | BO1: =IF(A1="","",A1) -> Jan 2016 | CA1: =IF(A1="","",A1) -> Jan 2016 | CJ1: =IF(A1="","",A1) -> Jan 2016 | CS1: =IF(A1="","",A1) -> Jan 2016 | DC1: =IF(A1="","",A1) -> Jan 2016 | DL1: =IF(A1="","",A1) -> Jan 2016 | DZ1: =IF(A1="","",A1) -> Jan 2016 | EB1: Compliance values such as maximum turbidity and minimum chlorine are transcribed directly from the Excel Daily Report print-outs | EI1: =IF(A1="","",A1) -> Jan 2016
A3: Drinking Water System | F3: Flows (1) | K3: =IF(A3="","",A3) -> Drinking Water System | O3: Flows (2) & Backwash Counters | W3: =IF(A3="","",A3) -> Drinking Water System | AB3: Low Lift & GAC Transfer Pumps | AG3: =IF(A3="","",A3) -> Drinking Water System | AL3: High Lift Pumps | AQ3: =IF(A3="","",A3) -> Drinking Water System | AV3: Other Pumps | BA3: =IF(A3="","",A3) -> Drinking Water System | BF3: Raw & Process Water Quality | BO3: =IF(A3="","",A3) -> Drinking Water System | BT3: Treated & Distribution Water Quality | CA3: =IF(A3="","",A3) -> Drinking Water System | CE3: Sodium Hypochlorite | CJ3: =IF(A3="","",A3) -> Drinking Water System | CN3: Watercare (PACl) | CS3: =IF(A3="","",A3) -> Drinking Water System | CW3: Polymer | DC3: =IF(A3="","",A3) -> Drinking Water System | DG3: Lime | DL3: =IF(A3="","",A3) -> Drinking Water System | DQ3: Analyzers | DZ3: =IF(A3="","",A3) -> Drinking Water System | EF3: Compliance | EI3: =IF(A3="","",A3) -> Drinking Water System | EM3: Comments
A4: Date | B4: Raw Water | E4: Treated Water | H4: GAC Transfer | J4: Operator Initials | K4: Date | L4: Backwash | N4: Wastewater | P4: Fire Pump | R4: Backwash Counters | V4: Operator Initials | W4: Date | X4: Low Lift Pumps | AB4: GAC Transfer Pumps | AF4: Operator Initials | AG4: Date | AH4: High Lift Pumps | AP4: Operator Initials | AQ4: Date | AR4: Wastewater Transfer Pumps | AV4: Backwash Pumps | AZ4: Operator Initials | BA4: Date | BB4: Raw Water | BG4: Coag. Water pH | BH4: Clarifiers | BJ4: SAF Filters | BL4: GAC Contactors | BN4: Operator Initials | BO4: Date | BP4: Treated (Point-of-Entry) Water | BW4: Distribution Water | BZ4: Operator Initials | CA4: Date | CB4: Tank Level (cm) | CC4: Filled Tank Level (cm) | CD4: Amount Used (cm) | CE4: Litres Used (L) | CF4: Actual Dosage (mg/L) | CG4: Chemical Feeder Speed Set Point (Freq.) | CH4: Chemical Feeder Stroke Set Point (%) | CI4: Operator Initials | CJ4: Date | CK4: Tank Level (cm) | CL4: Filled Tank Level (cm) | CM4: Amount Used (cm) | CN4: Litres Used (L) | CO4: Actual Dosage (mg/L) | CP4: Chemical Feeder Speed Set Point (Freq.) | CQ4: Chemical Feeder Stroke Set Point (%) | CR4: Operator Initials | CS4: Date | CT4: Tank Level (cm) | CU4: Filled Tank Level (or New Tank Level, if WW Polymer Filled) (cm) | CV4: Amount Used (cm) | CW4: Grams Used (g) | CX4: Actual Dosage (mg/L) | CY4: Chemical Feeder Speed Set Point (Freq.) | CZ4: Chemical Feeder Stroke Set Point (%) | DA4: Filled Wastewater Polymer Tank (Indicate Yes) | DB4: Operator Initials | DC4: Date | DD4: Tank Level (cm) | DE4: Filled Tank Level (cm) | DF4: Amount Used (cm) | DG4: Kilograms Used (kg) | DH4: Actual Dosage (mg/L) | DI4: Chemical Feeder Speed Set Point (Freq.) | DJ4: Chemical Feeder Stroke Set Point (%) | DK4: Operator Initials | DL4: Date | DM4: Raw | DN4: Filter Effluent | DP4: Treated (Point-of-Entry) | DV4: Process Wastewater | DY4: Operator Initials | DZ4: Date | EA4: Performance Data | ED4: Chlorine Residual | EF4: SAF #1 | EG4: SAF #2 | EH4: Operator Initials | EI4: Date | EJ4: Comments/Observations | EQ4: Operator Initials
B5: Meter Reading (m3) | C5: Total Flow (m3) | D5: Litres per Second (L/s) | E5: Meter Reading (m3) | F5: Total Flow (m3) | G5: Litres per Second (L/s) | H5: Meter Reading (m3) | I5: Total Flow (m3) | L5: Meter Reading (m3) | M5: Total Flow (m3) | N5: Meter Reading (m3) | O5: Total Flow (m3) | P5: Meter Reading (m3) | Q5: Total Flow (m3) | R5: SAF #1 | S5: SAF #2 | T5: GAC #1 | U5: GAC #2 | X5: LLP-1 | Z5: LLP-2 | AB5: GTP-1 | AD5: GTP-2 | AH5: HLP-1A | AJ5: HLP-1B | AL5: HLP-2 | AN5: HLP-3 | AR5: WWP-1 | AT5: WWP-2 | AV5: BWP-1 | AX5: BWP-2 | BB5: Turbidity (NTU) | BC5: Colour (PtCo) | BD5: pH | BE5: Temp. (oC) | BF5: Alkalinity (mg/L as CaCO3) | BH5: Clarifier #1 Turbidity (NTU) | BI5: Clarifier #2 Turbidity (NTU) | BJ5: SAF #1 Turbidity (NTU) | BK5: SAF #2 Turbidity (NTU) | BL5: GAC #1 Turbidity (NTU) | BM5: GAC #2 Turbidity (NTU) | BP5: Turbidity (NTU) | BQ5: Colour (PtCo) | BR5: pH | BS5: Temp. (oC) | BT5: Alkalinity (mg/L as CaCO3) | BU5: Aluminum Residual (mg/L) | BV5: Chlorine Residual (1o, mg/L) | BW5: Chlorine Residual (2o, mg/L) | BX5: Time of Chlorine Residual Sample | BY5: Sample Location | DM5: pH | DN5: SAF #1 Turbidity (NTU) | DO5: SAF #2 Turbidity (NTU) | DP5: Turbidity (NTU) | DQ5: pH | DR5: Temp. (oC) | DS5: Free Chlorine Residual (1o, mg/L) | DT5: Dist. Pressure (PSI) | DU5: Reservoir Level (m) | DV5: WW Surge Tank Level (m) | DW5: Suspended Solids (mg/L) | DX5: Decant in Progress (Y/N)? | EA5: Daily Raw Flow vs. PTTW Limit (%) | EB5: Daily Treated Flow vs. MDWL Limit (%) | EC5: Efficiency (Throughout) (%) | ED5: Treated (POE) | EF5: Maximum Turbidity (NTU) | EG5: Maximum Turbidity (NTU)
X6: Hour Meter Reading | Y6: Hours Run | Z6: Hour Meter Reading | AA6: Hours Run | AB6: Hour Meter Reading | AC6: Hours Run | AD6: Hour Meter Reading | AE6: Hours Run | AH6: Hour Meter Reading | AI6: Hours Run | AJ6: Hour Meter Reading | AK6: Hours Run | AL6: Hour Meter Reading | AM6: Hours Run | AN6: Hour Meter Reading | AO6: Hours Run | AR6: Hour Meter Reading | AS6: Hours Run | AT6: Hour Meter Reading | AU6: Hours Run | AV6: Hour Meter Reading | AW6: Hours Run | AX6: Hour Meter Reading | AY6: Hours Run | ED6: Minimum (mg/L) | EE6: Maximum (mg/L)
A8: 11 | B8: 859798 | C8: =IF(B9="","",IF(B9=B8,"",(B9-B8))) -> 185 | D8: 9.5 | E8: 764208 | F8: =IF(E9="","",IF(E9=E8,"",(E9-E8))) -> 147 | G8: 0.41 | H8: 728126 | I8: =IF(H9="","",IF(H9=H8,"",(H9-H8))) -> 128 | J8: SA/ME | K8: 1 | L8: 67390 | M8: =IF(L9="","",IF(L9=L8,"",(L9-L8))) -> 40 | N8: 169848 | O8: =IF(N9="","",IF(N9=N8,"",(N9-N8))) -> 51 | P8: 194713 | Q8: =IF(P9="","",IF(P9=P8,"",(P9-P8))) | R8: 651 | S8: 660 | T8: 136 | U8: 133 | V8: =IF(J8="","",J8) -> SA/ME | W8: 1 | X8: 11305.65 | Y8: =IF(X9="","",IF(X9=X8,"",X9-X8)) -> 3.43 | Z8: 12074.26 | AA8: =IF(Z9="","",IF(Z9=Z8,"",Z9-Z8)) -> 1.89 | AB8: 9557.72 | AC8: =IF(AB9="","",IF(AB9=AB8,"",AB9-AB8)) -> 2.04 | AD8: 9655.17 | AE8: =IF(AD9="","",IF(AD9=AD8,"",AD9-AD8)) -> 1.49 | AF8: =IF(J8="","",J8) -> SA/ME | AG8: 1 | AH8: 45038.49 | AI8: =IF(AH9="","",IF(AH9=AH8,"",AH9-AH8)) -> 15.83 | AJ8: 47177.24 | AK8: =IF(AJ9="","",IF(AJ9=AJ8,"",AJ9-AJ8)) -> 8.83 | AL8: 585.23 | AM8: =IF(AL9="","",IF(AL9=AL8,"",AL9-AL8)) | AN8: 546.24 | AO8: =IF(AN9="","",IF(AN9=AN8,"",AN9-AN8)) | AP8: =IF(J8="","",J8) -> SA/ME | AQ8: 1 | AR8: 6506.38 | AS8: =IF(AR9="","",IF(AR9=AR8,"",AR9-AR8)) | AT8: 7123.46 | AU8: =IF(AT9="","",IF(AT9=AT8,"",AT9-AT8)) -> 4.06 | AV8: 246.89 | AW8: =IF(AV9="","",IF(AV9=AV8,"",AV9-AV8)) -> 0.34 | AX8: 235.02 | AY8: =IF(AX9="","",IF(AX9=AX8,"",AX9-AX8)) | AZ8: =IF(J8="","",J8) -> SA/ME | BA8: 1 | BN8: =IF(J8="","",J8) -> SA/ME | BO8: 1 | BP8: 0.079 | BQ8: 0 | BR8: 7.3 | BS8: 7.5 | BT8: 16.7 | BU8: 0.027 | BV8: 1.08 | BW8: 0.98 | BX8: 1445 | BY8: 32 Willow St | BZ8: =IF(J8="","",J8) -> SA/ME | CA8: 1 | CB8: 84.2 | CD8: =IF(CB9="","",IF(CC8="",IF(CB8=CB9,"",(CB8-CB9)),IF(CC8=CB9,"",(CC8-CB9)))) -> 1.5 | CE8: =IF(CD8="","",(CD8*(0.785*77*77)/1000)) -> 6.9813975 | CF8: =IF(CE8="","",(CE8*0.12*1000)/I8) -> 6.5450602 | CG8: 125 | CH8: 100 | CI8: =IF(J8="","",J8) -> SA/ME | CJ8: 1 | CK8: 88.3 | CM8: =IF(CK9="","",IF(CL8="",IF(CK8=CK9,"",(CK8-CK9)),IF(CL8=CK9,"",(CL8-CK9)))) -> 2.1 | CN8: =IF(CM8="","",(CM8*(0.785*77*77)/1000)) -> 9.7739565 | CO8: =IF(CN8="","",(CN8*0.33*1.205*1000)/C8) -> 21.008723 | CP8: 54 | CQ8: 83 | CR8: =IF(J8="","",J8) -> SA/ME | CS8: 1 | CT8: 96.6 | CV8: =IF(CT9="","",IF(CU8="",IF(CT8=CT9,"",(CT8-CT9)),IF(CU8=CT9,"",(CU8-CT9)))) -> 1.6 | CW8: =IF(CV8="","",(CV8*(0.785*92*92)/1000)) -> 10.630784 | CX8: =IF(CW8="","",(CW8)/C8) -> 0.057463697 | CY8: 16/16 | CZ8: 100/100 | DB8: =IF(J8="","",J8) -> SA/ME | DC8: 1 | DD8: 88.2 | DE8: 105.7 | DF8: =IF(DD9="","",IF(DE8="",IF(DD8=DD9,"",(DD8-DD9)),IF(DE8=DD9,"",(DE8-DD9)))) -> 16.9 | DG8: =IF(DF8="","",(DF8*(0.785*92*92)*0.00812/1000)) -> 0.91177577 | DH8: =IF(DG8="","",(DG8*1000)/C8) -> 4.9285177 | DI8: 90 | DJ8: 54 | DK8: =IF(J8="","",J8) -> SA/ME | DL8: 1 | DM8: 8.5 | DN8: 0.021 | DO8: 0.025 | DP8: 0.052 | DQ8: 6.83 | DR8: 7.5 | DS8: 1.068 | DT8: 85 | DU8: 4.25 | DV8: 1.101 | DW8: 0.46 | DX8: Y | DY8: =IF(J8="","",J8) -> SA/ME | DZ8: 1 | EA8: =IF(C8="","",C8/1496) -> 0.1236631 | EB8: =IF(F8="","",IF(Q8="",F8/1360,(F8+Q8)/1360)) -> 0.10808824 | EC8: =IF(I8="","",IF(C8="","",I8/C8)) -> 0.69189189 | ED8: 0.03 | EE8: 0.09 | EF8: 1.06 | EG8: 1.1 | EH8: =IF(J8="","",J8) -> SA/ME | EI8: 1 | EQ8: =IF(J8="","",J8) -> SA/ME
A9: 2 | B9: 859983 | C9: =IF(B10="","",IF(B10=B9,"",(B10-B9))) -> 143 | D9: 8.96 | E9: 764355 | F9: =IF(E10="","",IF(E10=E9,"",(E10-E9))) -> 145 | G9: 1.24 | H9: 728254 | I9: =IF(H10="","",IF(H10=H9,"",(H10-H9))) -> 123 | J9: SA/ME | K9: 2 | L9: 67430 | M9: =IF(L10="","",IF(L10=L9,"",(L10-L9))) | N9: 169899 | O9: =IF(N10="","",IF(N10=N9,"",(N10-N9))) -> 47 | P9: 194713 | Q9: =IF(P10="","",IF(P10=P9,"",(P10-P9))) | R9: 652 | S9: 660 | T9: 136 | U9: 133 | V9: =IF(J9="","",J9) -> SA/ME | W9: 2 | X9: 11309.08 | Y9: =IF(X10="","",IF(X10=X9,"",X10-X9)) -> 2.21 | Z9: 12076.15 | AA9: =IF(Z10="","",IF(Z10=Z9,"",Z10-Z9)) -> 2.01 | AB9: 9559.76 | AC9: =IF(AB10="","",IF(AB10=AB9,"",AB10-AB9)) -> 1.76 | AD9: 9656.66 | AE9: =IF(AD10="","",IF(AD10=AD9,"",AD10-AD9)) -> 1.5 | AF9: =IF(J9="","",J9) -> SA/ME | AG9: 2 | AH9: 45054.32 | AI9: =IF(AH10="","",IF(AH10=AH9,"",AH10-AH9)) -> 8.17 | AJ9: 47186.07 | AK9: =IF(AJ10="","",IF(AJ10=AJ9,"",AJ10-AJ9)) -> 15.4 | AL9: 585.23 | AM9: =IF(AL10="","",IF(AL10=AL9,"",AL10-AL9)) | AN9: 546.24 | AO9: =IF(AN10="","",IF(AN10=AN9,"",AN10-AN9)) | AP9: =IF(J9="","",J9) -> SA/ME | AQ9: 2 | AR9: 6506.38 | AS9: =IF(AR10="","",IF(AR10=AR9,"",AR10-AR9)) | AT9: 7127.52 | AU9: =IF(AT10="","",IF(AT10=AT9,"",AT10-AT9)) -> 4.29 | AV9: 247.23 | AW9: =IF(AV10="","",IF(AV10=AV9,"",AV10-AV9)) | AX9: 235.02 | AY9: =IF(AX10="","",IF(AX10=AX9,"",AX10-AX9)) | AZ9: =IF(J9="","",J9) -> SA/ME | BA9: 2 | BB9: 0.788 | BC9: 41 | BD9: 7.4 | BE9: 2.6 | BF9: 16 | BG9: 7.4 | BH9: 0.381 | BI9: 0.384 | BJ9: 0.061 | BK9: 0.054 | BL9: 0.067 | BM9: 0.067 | BN9: =IF(J9="","",J9) -> SA/ME | BO9: 2 | BP9: 0.08 | BQ9: 0 | BR9: 7.3 | BS9: 7.4 | BT9: 14.7 | BU9: 0.008 | BV9: 1.16 | BW9: 0.99 | BX9: 1530 | BY9: 32 Willow St | BZ9: =IF(J9="","",J9) -> SA/ME | CA9: 2 | CB9: 82.7 | CD9: =IF(CB10="","",IF(CC9="",IF(CB9=CB10,"",(CB9-CB10)),IF(CC9=CB10,"",(CC9-CB10)))) -> 1.1 | CE9: =IF(CD9="","",(CD9*(0.785*77*77)/1000)) -> 5.1196915 | CF9: =IF(CE9="","",(CE9*0.12*1000)/I9) -> 4.994821 | CG9: 125 | CH9: 100 | CI9: =IF(J9="","",J9) -> SA/ME | CJ9: 2 | CK9: 86.2 | CM9: =IF(CK10="","",IF(CL9="",IF(CK9=CK10,"",(CK9-CK10)),IF(CL9=CK10,"",(CL9-CK10)))) -> 1.6 | CN9: =IF(CM9="","",(CM9*(0.785*77*77)/1000)) -> 7.446824 | CO9: =IF(CN9="","",(CN9*0.33*1.205*1000)/C9) -> 20.707899 | CP9: 54 | CQ9: 83 | CR9: =IF(J9="","",J9) -> SA/ME | CS9: 2 | CT9: 95 | CV9: =IF(CT10="","",IF(CU9="",IF(CT9=CT10,"",(CT9-CT10)),IF(CU9=CT10,"",(CU9-CT10)))) -> 3.5 | CW9: =IF(CV9="","",(CV9*(0.785*92*92)/1000)) -> 23.25484 | CX9: =IF(CW9="","",(CW9)/C9) -> 0.16262126 | CY9: 16/16 | CZ9: 100/100 | DB9: =IF(J9="","",J9) -> SA/ME | DC9: 2 | DD9: 88.8 | DE9: 103.2 | DF9: =IF(DD10="","",IF(DE9="",IF(DD9=DD10,"",(DD9-DD10)),IF(DE9=DD10,"",(DE9-DD10)))) -> 9.3 | DG9: =IF(DF9="","",(DF9*(0.785*92*92)*0.00812/1000)) -> 0.50174643 | DH9: =IF(DG9="","",(DG9*1000)/C9) -> 3.5087163 | DI9: 90 | DJ9: 54 | DK9: =IF(J9="","",J9) -> SA/ME | DL9: 2 | DM9: 8.53 | DN9: 0.009 | DO9: 0.021 | DP9: 0.052 | DQ9: 6.84 | DR9: 7.4 | DS9: 1.126 | DT9: 86.6 | DU9: 4.28 | DV9: 1.746 | DW9: 0.891 | DX9: Y | DY9: =IF(J9="","",J9) -> SA/ME | DZ9: 2 | EA9: =IF(C9="","",C9/1496) -> 0.095588235 | EB9: =IF(F9="","",IF(Q9="",F9/1360,(F9+Q9)/1360)) -> 0.10661765 | EC9: =IF(I9="","",IF(C9="","",I9/C9)) -> 0.86013986 | ED9: 0.03 | EE9: 0.04 | EF9: 1.05 | EG9: 1.16 | EH9: =IF(J9="","",J9) -> SA/ME | EI9: 2 | EQ9: =IF(J9="","",J9) -> SA/ME
A10: 3 | B10: 860126 | C10: =IF(B11="","",IF(B11=B10,"",(B11-B10))) -> 106 | D10: 8.95 | E10: 764500 | F10: =IF(E11="","",IF(E11=E10,"",(E11-E10))) -> 133 | G10: 0.79 | H10: 728377 | I10: =IF(H11="","",IF(H11=H10,"",(H11-H10))) -> 81 | J10: SA/ME | K10: 3 | L10: 67430 | M10: =IF(L11="","",IF(L11=L10,"",(L11-L10))) | N10: 169946 | O10: =IF(N11="","",IF(N11=N10,"",(N11-N10))) -> 35 | P10: 194713 | Q10: =IF(P11="","",IF(P11=P10,"",(P11-P10))) | R10: 652 | S10: 660 | T10: 136 | U10: 133 | V10: =IF(J10="","",J10) -> SA/ME | W10: 3 | X10: 11311.29 | Y10: =IF(X11="","",IF(X11=X10,"",X11-X10)) -> 1.4 | Z10: 12078.16 | AA10: =IF(Z11="","",IF(Z11=Z10,"",Z11-Z10)) -> 1.92 | AB10: 9561.52 | AC10: =IF(AB11="","",IF(AB11=AB10,"",AB11-AB10)) -> 0.6 | AD10: 9658.16 | AE10: =IF(AD11="","",IF(AD11=AD10,"",AD11-AD10)) -> 1.48 | AF10: =IF(J10="","",J10) -> SA/ME | AG10: 3 | AH10: 45062.49 | AI10: =IF(AH11="","",IF(AH11=AH10,"",AH11-AH10)) -> 15.69 | AJ10: 47201.47 | AK10: =IF(AJ11="","",IF(AJ11=AJ10,"",AJ11-AJ10)) -> 8.6 | AL10: 585.23 | AM10: =IF(AL11="","",IF(AL11=AL10,"",AL11-AL10)) | AN10: 546.24 | AO10: =IF(AN11="","",IF(AN11=AN10,"",AN11-AN10)) | AP10: =IF(J10="","",J10) -> SA/ME | AQ10: 3 | AR10: 6506.38 | AS10: =IF(AR11="","",IF(AR11=AR10,"",AR11-AR10)) | AT10: 7131.81 | AU10: =IF(AT11="","",IF(AT11=AT10,"",AT11-AT10)) -> 4.05 | AV10: 247.23 | AW10: =IF(AV11="","",IF(AV11=AV10,"",AV11-AV10)) | AX10: 235.02 | AY10: =IF(AX11="","",IF(AX11=AX10,"",AX11-AX10)) | AZ10: =IF(J10="","",J10) -> SA/ME | BA10: 3 | BB10: 0.757 | BC10: 13 | BD10: 7.3 | BE10: 2.6 | BF10: 16.8 | BG10: 7.3 | BH10: 0.414 | BI10: 0.411 | BJ10: 0.048 | BK10: 0.048 | BL10: 0.054 | BM10: 0.063 | BN10: =IF(J10="","",J10) -> SA/ME | BO10: 3 | BP10: 0.076 | BQ10: 0 | BR10: 7.3 | BS10: 7.3 | BT10: 16.9 | BU10: 0.009 | BV10: 1.23 | BW10: 1.01 | BX10: 1510 | BY10: 32 Willow St | BZ10: =IF(J10="","",J10) -> SA/ME | CA10: 3 | CB10: 81.6 | CD10: =IF(CB11="","",IF(CC10="",IF(CB10=CB11,"",(CB10-CB11)),IF(CC10=CB11,"",(CC10-CB11)))) -> 1.1 | CE10: =IF(CD10="","",(CD10*(0.785*77*77)/1000)) -> 5.1196915 | CF10: =IF(CE10="","",(CE10*0.12*1000)/I10) -> 7.5847281 | CG10: 125 | CH10: 100 | CI10: =IF(J10="","",J10) -> SA/ME | CJ10: 3 | CK10: 84.6 | CM10: =IF(CK11="","",IF(CL10="",IF(CK10=CK11,"",(CK10-CK11)),IF(CL10=CK11,"",(CL10-CK11)))) -> 1.5 | CN10: =IF(CM10="","",(CM10*(0.785*77*77)/1000)) -> 6.9813975 | CO10: =IF(CN10="","",(CN10*0.33*1.205*1000)/C10) -> 26.19012 | CP10: 54 | CQ10: 83 | CR10: =IF(J10="","",J10) -> SA/ME | CS10: 3 | CT10: 91.5 | CV10: =IF(CT11="","",IF(CU10="",IF(CT10=CT11,"",(CT10-CT11)),IF(CU10=CT11,"",(CU10-CT11)))) -> 1.2 | CW10: =IF(CV10="","",(CV10*(0.785*92*92)/1000)) -> 7.973088 | CX10: =IF(CW10="","",(CW10)/C10) -> 0.075217811 | CY10: 16/16 | CZ10: 100/100 | DA10: Y | DB10: =IF(J10="","",J10) -> SA/ME | DC10: 3 | DD10: 93.9 | DE10: 106.1 | DF10: =IF(DD11="","",IF(DE10="",IF(DD10=DD11,"",(DD10-DD11)),IF(DE10=DD11,"",(DE10-DD11)))) -> 7.2 | DG10: =IF(DF10="","",(DF10*(0.785*92*92)*0.00812/1000)) -> 0.38844885 | DH10: =IF(DG10="","",(DG10*1000)/C10) -> 3.6646118 | DI10: 90 | DJ10: 54 | DK10: =IF(J10="","",J10) -> SA/ME | DL10: 3 | DM10: 7.9 | DN10: 0.01 | DO10: 0.026 | DP10: 0.051 | DQ10: 6.83 | DR10: 7.3 | DS10: 1.18 | DT10: 86 | DU10: 4.28 | DV10: 1.089 | DW10: 1.11 | DX10: Y | DY10: =IF(J10="","",J10) -> SA/ME | DZ10: 3 | EA10: =IF(C10="","",C10/1496) -> 0.070855615 | EB10: =IF(F10="","",IF(Q10="",F10/1360,(F10+Q10)/1360)) -> 0.097794118 | EC10: =IF(I10="","",IF(C10="","",I10/C10)) -> 0.76415094 | ED10: 1.11 | EE10: 1.19 | EF10: 0.03 | EG10: 0.05 | EH10: =IF(J10="","",J10) -> SA/ME | EI10: 3 | EQ10: =IF(J10="","",J10) -> SA/ME
A11: 4 | B11: 860232 | C11: =IF(B12="","",IF(B12=B11,"",(B12-B11))) -> 139 | D11: 9.13 | E11: 764633 | F11: =IF(E12="","",IF(E12=E11,"",(E12-E11))) -> 166 | G11: 1.08 | H11: 728458 | I11: =IF(H12="","",IF(H12=H11,"",(H12-H11))) -> 117 | J11: ME | K11: 4 | L11: 67430 | M11: =IF(L12="","",IF(L12=L11,"",(L12-L11))) | N11: 169981 | O11: =IF(N12="","",IF(N12=N11,"",(N12-N11))) -> 29 | P11: 194713 | Q11: =IF(P12="","",IF(P12=P11,"",(P12-P11))) | R11: 652 | S11: 660 | T11: 136 | U11: 133 | V11: =IF(J11="","",J11) -> ME | W11: 4 | X11: 11312.69 | Y11: =IF(X12="","",IF(X12=X11,"",X12-X11)) -> 2.01 | Z11: 12080.08 | AA11: =IF(Z12="","",IF(Z12=Z11,"",Z12-Z11)) -> 2.04 | AB11: 9562.12 | AC11: =IF(AB12="","",IF(AB12=AB11,"",AB12-AB11)) -> 1.54 | AD11: 9659.64 | AE11: =IF(AD12="","",IF(AD12=AD11,"",AD12-AD11)) -> 1.58 | AF11: =IF(J11="","",J11) -> ME | AG11: 4 | AH11: 45078.18 | AI11: =IF(AH12="","",IF(AH12=AH11,"",AH12-AH11)) -> 8.32 | AJ11: 47210.07 | AK11: =IF(AJ12="","",IF(AJ12=AJ11,"",AJ12-AJ11)) -> 13.73 | AL11: 585.23 | AM11: =IF(AL12="","",IF(AL12=AL11,"",AL12-AL11)) | AN11: 546.24 | AO11: =IF(AN12="","",IF(AN12=AN11,"",AN12-AN11)) | AP11: =IF(J11="","",J11) -> ME | AQ11: 4 | AR11: 6506.38 | AS11: =IF(AR12="","",IF(AR12=AR11,"",AR12-AR11)) -> 0.22 | AT11: 7135.86 | AU11: =IF(AT12="","",IF(AT12=AT11,"",AT12-AT11)) -> 2.92 | AV11: 247.23 | AW11: =IF(AV12="","",IF(AV12=AV11,"",AV12-AV11)) | AX11: 235.02 | AY11: =IF(AX12="","",IF(AX12=AX11,"",AX12-AX11)) | AZ11: =IF(J11="","",J11) -> ME | BA11: 4 | BB11: 0.781 | BC11: 36 | BD11: 7.3 | BE11: 2.6 | BF11: 16.6 | BG11: 7.3 | BH11: 0.24 | BI11: 0.236 | BJ11: 0.052 | BK11: 0.054 | BL11: 0.052 | BM11: 0.055 | BN11: =IF(J11="","",J11) -> ME | BO11: 4 | BP11: 0.075 | BQ11: 0 | BR11: 7.3 | BS11: 7.4 | BT11: 17.7 | BU11: 0.011 | BV11: 1.18 | BW11: 0.94 | BX11: 0620 | BY11: 60 Livengood | BZ11: =IF(J11="","",J11) -> ME | CA11: 4 | CB11: 80.5 | CC11: 90.8 | CD11: =IF(CB12="","",IF(CC11="",IF(CB11=CB12,"",(CB11-CB12)),IF(CC11=CB12,"",(CC11-CB12)))) -> 1.4 | CE11: =IF(CD11="","",(CD11*(0.785*77*77)/1000)) -> 6.515971 | CF11: =IF(CE11="","",(CE11*0.12*1000)/I11) -> 6.6830472 | CG11: 128 | CH11: 100 | CI11: =IF(J11="","",J11) -> ME | CJ11: 4 | CK11: 83.1 | CL11: 93.5 | CM11: =IF(CK12="","",IF(CL11="",IF(CK11=CK12,"",(CK11-CK12)),IF(CL11=CK12,"",(CL11-CK12)))) -> 1.8 | CN11: =IF(CM11="","",(CM11*(0.785*77*77)/1000)) -> 8.377677 | CO11: =IF(CN11="","",(CN11*0.33*1.205*1000)/C11) -> 23.966786 | CP11: 53 | CQ11: 83 | CR11: =IF(J11="","",J11) -> ME | CS11: 4 | CT11: 90.3 | CU11: 113.5 | CV11: =IF(CT12="","",IF(CU11="",IF(CT11=CT12,"",(CT11-CT12)),IF(CU11=CT12,"",(CU11-CT12)))) -> 1.3 | CW11: =IF(CV11="","",(CV11*(0.785*92*92)/1000)) -> 8.637512 | CX11: =IF(CW11="","",(CW11)/C11) -> 0.062140374 | CY11: 16/16 | CZ11: 100/100 | DB11: =IF(J11="","",J11) -> ME | DC11: 4 | DD11: 98.9 | DF11: =IF(DD12="","",IF(DE11="",IF(DD11=DD12,"",(DD11-DD12)),IF(DE11=DD12,"",(DE11-DD12)))) -> 10.9 | DG11: =IF(DF11="","",(DF11*(0.785*92*92)*0.00812/1000)) -> 0.58806839 | DH11: =IF(DG11="","",(DG11*1000)/C11) -> 4.2307079 | DI11: 90 | DJ11: 54 | DK11: =IF(J11="","",J11) -> ME | DL11: 4 | DM11: 8.79 | DN11: 0.023 | DO11: 0.028 | DP11: 0.052 | DQ11: 6.84 | DR11: 7.4 | DS11: 1.189 | DT11: 87.4 | DU11: 4.2 | DV11: 0.709 | DW11: 3.9 | DX11: N | DY11: =IF(J11="","",J11) -> ME | DZ11: 4 | EA11: =IF(C11="","",C11/1496) -> 0.092914439 | EB11: =IF(F11="","",IF(Q11="",F11/1360,(F11+Q11)/1360)) -> 0.12205882 | EC11: =IF(I11="","",IF(C11="","",I11/C11)) -> 0.84172662 | ED11: 1.1 | EE11: 1.2 | EF11: 0.03 | EG11: 0.04 | EH11: =IF(J11="","",J11) -> ME | EI11: 4 | EQ11: =IF(J11="","",J11) -> ME
A12: 5 | B12: 860371 | C12: =IF(B13="","",IF(B13=B12,"",(B13-B12))) -> 218 | D12: 9.3 | E12: 764799 | F12: =IF(E13="","",IF(E13=E12,"",(E13-E12))) -> 164 | G12: 1.88 | H12: 728575 | I12: =IF(H13="","",IF(H13=H12,"",(H13-H12))) -> 148 | J12: ME | K12: 5 | L12: 67430 | M12: =IF(L13="","",IF(L13=L12,"",(L13-L12))) -> 41 | N12: 170010 | O12: =IF(N13="","",IF(N13=N12,"",(N13-N12))) -> 40 | P12: 194713 | Q12: =IF(P13="","",IF(P13=P12,"",(P13-P12))) | R12: 652 | S12: 660 | T12: 136 | U12: 133 | V12: =IF(J12="","",J12) -> ME | W12: 5 | X12: 11314.7 | Y12: =IF(X13="","",IF(X13=X12,"",X13-X12)) -> 4.56 | Z12: 12082.12 | AA12: =IF(Z13="","",IF(Z13=Z12,"",Z13-Z12)) -> 1.95 | AB12: 9563.66 | AC12: =IF(AB13="","",IF(AB13=AB12,"",AB13-AB12)) -> 3.59 | AD12: 9661.22 | AE12: =IF(AD13="","",IF(AD13=AD12,"",AD13-AD12)) -> 0.36 | AF12: =IF(J12="","",J12) -> ME | AG12: 5 | AH12: 45086.5 | AI12: =IF(AH13="","",IF(AH13=AH12,"",AH13-AH12)) -> 15.61 | AJ12: 47223.8 | AK12: =IF(AJ13="","",IF(AJ13=AJ12,"",AJ13-AJ12)) -> 10.28 | AL12: 585.23 | AM12: =IF(AL13="","",IF(AL13=AL12,"",AL13-AL12)) -> 0.03 | AN12: 546.24 | AO12: =IF(AN13="","",IF(AN13=AN12,"",AN13-AN12)) | AP12: =IF(J12="","",J12) -> ME | AQ12: 5 | AR12: 6506.6 | AS12: =IF(AR13="","",IF(AR13=AR12,"",AR13-AR12)) | AT12: 7138.78 | AU12: =IF(AT13="","",IF(AT13=AT12,"",AT13-AT12)) -> 3.59 | AV12: 247.23 | AW12: =IF(AV13="","",IF(AV13=AV12,"",AV13-AV12)) | AX12: 235.02 | AY12: =IF(AX13="","",IF(AX13=AX12,"",AX13-AX12)) -> 0.34 | AZ12: =IF(J12="","",J12) -> ME | BA12: 5 | BB12: 0.872 | BC12: 27 | BD12: 7.4 | BE12: 2.6 | BF12: 17.1 | BG12: 7.4 | BH12: 0.331 | BI12: 0.365 | BJ12: 0.6 | BK12: 0.048 | BL12: 0.067 | BM12: 0.063 | BN12: =IF(J12="","",J12) -> ME | BO12: 5 | BP12: 0.076 | BQ12: 0 | BR12: 7.3 | BS12: 7.4 | BT12: 18.6 | BU12: 0.013 | BV12: 1.32 | BW12: 0.87 | BX12: 0620 | BY12: 60 Livengood | BZ12: =IF(J12="","",J12) -> ME | CA12: 5 | CB12: 89.4 | CD12: =IF(CB13="","",IF(CC12="",IF(CB12=CB13,"",(CB12-CB13)),IF(CC12=CB13,"",(CC12-CB13)))) -> 0.8 | CE12: =IF(CD12="","",(CD12*(0.785*77*77)/1000)) -> 3.723412 | CF12: =IF(CE12="","",(CE12*0.12*1000)/I12) -> 3.0189827 | CG12: 123 | CH12: 100 | CI12: =IF(J12="","",J12) -> ME | CJ12: 5 | CK12: 91.7 | CM12: =IF(CK13="","",IF(CL12="",IF(CK12=CK13,"",(CK12-CK13)),IF(CL12=CK13,"",(CL12-CK13)))) -> 2.7 | CN12: =IF(CM12="","",(CM12*(0.785*77*77)/1000)) -> 12.566516 | CO12: =IF(CN12="","",(CN12*0.33*1.205*1000)/C12) -> 22.922362 | CP12: 52 | CQ12: 83 | CR12: =IF(J12="","",J12) -> ME | CS12: 5 | CT12: 112.2 | CU12: 107.8 | CV12: =IF(CT13="","",IF(CU12="",IF(CT12=CT13,"",(CT12-CT13)),IF(CU12=CT13,"",(CU12-CT13)))) -> 2 | CW12: =IF(CV12="","",(CV12*(0.785*92*92)/1000)) -> 13.28848 | CX12: =IF(CW12="","",(CW12)/C12) -> 0.06095633 | CY12: 16/16 | CZ12: 100/100 | DA12: Y | DB12: =IF(J12="","",J12) -> ME | DC12: 5 | DD12: 88 | DE12: 104.4 | DF12: =IF(DD13="","",IF(DE12="",IF(DD12=DD13,"",(DD12-DD13)),IF(DE12=DD13,"",(DE12-DD13)))) -> 18.6 | DG12: =IF(DF12="","",(DF12*(0.785*92*92)*0.00812/1000)) -> 1.0034929 | DH12: =IF(DG12="","",(DG12*1000)/C12) -> 4.6031782 | DI12: 90 | DJ12: 54 | DK12: =IF(J12="","",J12) -> ME | DL12: 5 | DM12: 8.56 | DN12: 0.023 | DO12: 0.026 | DP12: 0.057 | DQ12: 6.84 | DR12: 7.4 | DS12: 1.221 | DT12: 85.6 | DU12: 4.15 | DV12: 0.68 | DW12: 0.588 | DX12: Y | DY12: =IF(J12="","",J12) -> ME | DZ12: 5 | EA12: =IF(C12="","",C12/1496) -> 0.14572193 | EB12: =IF(F12="","",IF(Q12="",F12/1360,(F12+Q12)/1360)) -> 0.12058824 | EC12: =IF(I12="","",IF(C12="","",I12/C12)) -> 0.67889908 | ED12: 1.16 | EE12: 1.24 | EF12: 0.03 | EG12: 0.04 | EH12: =IF(J12="","",J12) -> ME | EI12: 5 | EQ12: =IF(J12="","",J12) -> ME
A13: 6 | B13: 860589 | C13: =IF(B14="","",IF(B14=B13,"",(B14-B13))) -> 138 | D13: 9 | E13: 764963 | F13: =IF(E14="","",IF(E14=E13,"",(E14-E13))) -> 143 | G13: 2.31 | H13: 728723 | I13: =IF(H14="","",IF(H14=H13,"",(H14-H13))) -> 116 | J13: ME | K13: 6 | L13: 67471 | M13: =IF(L14="","",IF(L14=L13,"",(L14-L13))) | N13: 170050 | O13: =IF(N14="","",IF(N14=N13,"",(N14-N13))) -> 42 | P13: 194713 | Q13: =IF(P14="","",IF(P14=P13,"",(P14-P13))) | R13: 652 | S13: 661 | T13: 136 | U13: 133 | V13: =IF(J13="","",J13) -> ME | W13: 6 | X13: 11319.26 | Y13: =IF(X14="","",IF(X14=X13,"",X14-X13)) -> 1.96 | Z13: 12084.07 | AA13: =IF(Z14="","",IF(Z14=Z13,"",Z14-Z13)) -> 2.09 | AB13: 9567.25 | AC13: =IF(AB14="","",IF(AB14=AB13,"",AB14-AB13)) -> 1.49 | AD13: 9661.58 | AE13: =IF(AD14="","",IF(AD14=AD13,"",AD14-AD13)) -> 1.62 | AF13: =IF(J13="","",J13) -> ME | AG13: 6 | AH13: 45102.11 | AI13: =IF(AH14="","",IF(AH14=AH13,"",AH14-AH13)) -> 8.4 | AJ13: 47234.08 | AK13: =IF(AJ14="","",IF(AJ14=AJ13,"",AJ14-AJ13)) -> 14.74 | AL13: 585.26 | AM13: =IF(AL14="","",IF(AL14=AL13,"",AL14-AL13)) | AN13: 546.24 | AO13: =IF(AN14="","",IF(AN14=AN13,"",AN14-AN13)) | AP13: =IF(J13="","",J13) -> ME | AQ13: 6 | AR13: 6506.6 | AS13: =IF(AR14="","",IF(AR14=AR13,"",AR14-AR13)) | AT13: 7142.37 | AU13: =IF(AT14="","",IF(AT14=AT13,"",AT14-AT13)) -> 3.4 | AV13: 247.23 | AW13: =IF(AV14="","",IF(AV14=AV13,"",AV14-AV13)) | AX13: 235.36 | AY13: =IF(AX14="","",IF(AX14=AX13,"",AX14-AX13)) | AZ13: =IF(J13="","",J13) -> ME | BA13: 6 | BN13: =IF(J13="","",J13) -> ME | BO13: 6 | BP13: 0.079 | BQ13: 0 | BR13: 7.4 | BS13: 7.4 | BT13: 16.6 | BU13: 0.015 | BV13: 1.24 | BW13: 0.87 | BX13: 0635 | BY13: 60 Livengood | BZ13: =IF(J13="","",J13) -> ME | CA13: 6 | CB13: 88.6 | CD13: =IF(CB14="","",IF(CC13="",IF(CB13=CB14,"",(CB13-CB14)),IF(CC13=CB14,"",(CC13-CB14)))) -> 1.1 | CE13: =IF(CD13="","",(CD13*(0.785*77*77)/1000)) -> 5.1196915 | CF13: =IF(CE13="","",(CE13*0.12*1000)/I13) -> 5.2962326 | CG13: 125 | CH13: 100 | CI13: =IF(J13="","",J13) -> ME | CJ13: 6 | CK13: 89 | CM13: =IF(CK14="","",IF(CL13="",IF(CK13=CK14,"",(CK13-CK14)),IF(CL13=CK14,"",(CL13-CK14)))) -> 1.6 | CN13: =IF(CM13="","",(CM13*(0.785*77*77)/1000)) -> 7.446824 | CO13: =IF(CN13="","",(CN13*0.33*1.205*1000)/C13) -> 21.458185 | CP13: 53 | CQ13: 83 | CR13: =IF(J13="","",J13) -> ME | CS13: 6 | CT13: 105.8 | CV13: =IF(CT14="","",IF(CU13="",IF(CT13=CT14,"",(CT13-CT14)),IF(CU13=CT14,"",(CU13-CT14)))) -> 1.6 | CW13: =IF(CV13="","",(CV13*(0.785*92*92)/1000)) -> 10.630784 | CX13: =IF(CW13="","",(CW13)/C13) -> 0.077034667 | CY13: 16/16 | CZ13: 100/100 | DB13: =IF(J13="","",J13) -> ME | DC13: 6 | DD13: 85.8 | DE13: 103 | DF13: =IF(DD14="","",IF(DE13="",IF(DD13=DD14,"",(DD13-DD14)),IF(DE13=DD14,"",(DE13-DD14)))) -> 11.8 | DG13: =IF(DF13="","",(DF13*(0.785*92*92)*0.00812/1000)) -> 0.6366245 | DH13: =IF(DG13="","",(DG13*1000)/C13) -> 4.613221 | DI13: 90 | DJ13: 54 | DK13: =IF(J13="","",J13) -> ME | DL13: 6 | DM13: 9.05 | DN13: 0.022 | DO13: 0.027 | DP13: 4.276 | DQ13: 6.83 | DR13: 7.4 | DS13: 1.196 | DT13: 86.7 | DU13: 4.2 | DV13: 0.723 | DW13: 1.861 | DX13: Y | DY13: =IF(J13="","",J13) -> ME | DZ13: 6 | EA13: =IF(C13="","",C13/1496) -> 0.092245989 | EB13: =IF(F13="","",IF(Q13="",F13/1360,(F13+Q13)/1360)) -> 0.10514706 | EC13: =IF(I13="","",IF(C13="","",I13/C13)) -> 0.84057971 | ED13: 0.91 | EE13: 1.24 | EF13: 0.03 | EG13: 0.05 | EH13: =IF(J13="","",J13) -> ME | EI13: 6 | EJ13: Tanker filling @ Fire Hall momentary dip in CL2 and spike in turbidity (ME) | EQ13: =IF(J13="","",J13) -> ME
A14: 7 | B14: 860727 | C14: =IF(B15="","",IF(B15=B14,"",(B15-B14))) -> 144 | D14: 9.4 | E14: 765106 | F14: =IF(E15="","",IF(E15=E14,"",(E15-E14))) -> 149 | G14: 3.38 | H14: 728839 | I14: =IF(H15="","",IF(H15=H14,"",(H15-H14))) -> 122 | J14: ME | K14: 7 | L14: 67471 | M14: =IF(L15="","",IF(L15=L14,"",(L15-L14))) -> 1 | N14: 170092 | O14: =IF(N15="","",IF(N15=N14,"",(N15-N14))) -> 37 | P14: 194713 | Q14: =IF(P15="","",IF(P15=P14,"",(P15-P14))) | R14: 652 | S14: 661 | T14: 136 | U14: 133 | V14: =IF(J14="","",J14) -> ME | W14: 7 | X14: 11321.22 | Y14: =IF(X15="","",IF(X15=X14,"",X15-X14)) -> 2.02 | Z14: 12086.16 | AA14: =IF(Z15="","",IF(Z15=Z14,"",Z15-Z14)) -> 2.21 | AB14: 9568.74 | AC14: =IF(AB15="","",IF(AB15=AB14,"",AB15-AB14)) -> 1.58 | AD14: 9663.2 | AE14: =IF(AD15="","",IF(AD15=AD14,"",AD15-AD14)) -> 1.64 | AF14: =IF(J14="","",J14) -> ME | AG14: 7 | AH14: 45110.51 | AI14: =IF(AH15="","",IF(AH15=AH14,"",AH15-AH14)) -> 10.4 | AJ14: 47248.82 | AK14: =IF(AJ15="","",IF(AJ15=AJ14,"",AJ15-AJ14)) -> 9.27 | AL14: 585.26 | AM14: =IF(AL15="","",IF(AL15=AL14,"",AL15-AL14)) | AN14: 546.24 | AO14: =IF(AN15="","",IF(AN15=AN14,"",AN15-AN14)) -> 0.1 | AP14: =IF(J14="","",J14) -> ME | AQ14: 7 | AR14: 6506.6 | AS14: =IF(AR15="","",IF(AR15=AR14,"",AR15-AR14)) -> 0.55 | AT14: 7145.77 | AU14: =IF(AT15="","",IF(AT15=AT14,"",AT15-AT14)) -> 3.02 | AV14: 247.23 | AW14: =IF(AV15="","",IF(AV15=AV14,"",AV15-AV14)) | AX14: 235.36 | AY14: =IF(AX15="","",IF(AX15=AX14,"",AX15-AX14)) | AZ14: =IF(J14="","",J14) -> ME | BA14: 7 | BN14: =IF(J14="","",J14) -> ME | BO14: 7 | BP14: 0.099 | BQ14: 0 | BR14: 7.3 | BS14: 7.4 | BT14: 18 | BU14: 0.013 | BV14: 1.24 | BW14: 1.11 | BX14: 0540 | BY14: 60 Livengood | BZ14: =IF(J14="","",J14) -> ME | CA14: 7 | CB14: 87.5 | CD14: =IF(CB15="","",IF(CC14="",IF(CB14=CB15,"",(CB14-CB15)),IF(CC14=CB15,"",(CC14-CB15)))) -> 0.9 | CE14: =IF(CD14="","",(CD14*(0.785*77*77)/1000)) -> 4.1888385 | CF14: =IF(CE14="","",(CE14*0.12*1000)/I14) -> 4.120169 | CG14: 123 | CH14: 100 | CI14: =IF(J14="","",J14) -> ME | CJ14: 7 | CK14: 87.4 | CM14: =IF(CK15="","",IF(CL14="",IF(CK14=CK15,"",(CK14-CK15)),IF(CL14=CK15,"",(CL14-CK15)))) -> 1.8 | CN14: =IF(CM14="","",(CM14*(0.785*77*77)/1000)) -> 8.377677 | CO14: =IF(CN14="","",(CN14*0.33*1.205*1000)/C14) -> 23.134606 | CP14: 53 | CQ14: 83 | CR14: =IF(J14="","",J14) -> ME | CS14: 7 | CT14: 104.2 | CV14: =IF(CT15="","",IF(CU14="",IF(CT14=CT15,"",(CT14-CT15)),IF(CU14=CT15,"",(CU14-CT15)))) -> 1.5 | CW14: =IF(CV14="","",(CV14*(0.785*92*92)/1000)) -> 9.96636 | CX14: =IF(CW14="","",(CW14)/C14) -> 0.069210833 | CY14: 16/16 | CZ14: 100/100 | DB14: =IF(J14="","",J14) -> ME | DC14: 7 | DD14: 91.2 | DE14: 103.9 | DF14: =IF(DD15="","",IF(DE14="",IF(DD14=DD15,"",(DD14-DD15)),IF(DE14=DD15,"",(DE14-DD15)))) -> 12.3 | DG14: =IF(DF14="","",(DF14*(0.785*92*92)*0.00812/1000)) -> 0.66360011 | DH14: =IF(DG14="","",(DG14*1000)/C14) -> 4.6083341 | DI14: 90 | DJ14: 54 | DK14: =IF(J14="","",J14) -> ME | DL14: 7 | DM14: 8.43 | DN14: 0.023 | DO14: 0.03 | DP14: 0.081 | DQ14: 6.84 | DR14: 7.4 | DS14: 1.205 | DT14: 86.8 | DU14: 4.2 | DV14: 1.394 | DW14: 0.722 | DX14: Y | DY14: =IF(J14="","",J14) -> ME | DZ14: 7 | EA14: =IF(C14="","",C14/1496) -> 0.096256684 | EB14: =IF(F14="","",IF(Q14="",F14/1360,(F14+Q14)/1360)) -> 0.10955882 | EC14: =IF(I14="","",IF(C14="","",I14/C14)) -> 0.84722222 | ED14: 0.98 | EE14: 1.2 | EF14: 0.04 | EG14: 0.05 | EH14: =IF(J14="","",J14) -> ME | EI14: 7 | EJ14: Tanker filling @ Fire Hall momentary dip in CL2 and spike in turbidity (ME) | EQ14: =IF(J14="","",J14) -> ME
A15: 8 | B15: 860871 | C15: =IF(B16="","",IF(B16=B15,"",(B16-B15))) -> 154 | D15: 9.82 | E15: 765255 | F15: =IF(E16="","",IF(E16=E15,"",(E16-E15))) -> 159 | G15: 2.4 | H15: 728961 | I15: =IF(H16="","",IF(H16=H15,"",(H16-H15))) -> 133 | J15: ME | K15: 8 | L15: 67472 | M15: =IF(L16="","",IF(L16=L15,"",(L16-L15))) | N15: 170129 | O15: =IF(N16="","",IF(N16=N15,"",(N16-N15))) -> 40 | P15: 194713 | Q15: =IF(P16="","",IF(P16=P15,"",(P16-P15))) | R15: 652 | S15: 661 | T15: 136 | U15: 133 | V15: =IF(J15="","",J15) -> ME | W15: 8 | X15: 11323.24 | Y15: =IF(X16="","",IF(X16=X15,"",X16-X15)) -> 2.15 | Z15: 12088.37 | AA15: =IF(Z16="","",IF(Z16=Z15,"",Z16-Z15)) -> 2.23 | AB15: 9570.32 | AC15: =IF(AB16="","",IF(AB16=AB15,"",AB16-AB15)) -> 1.71 | AD15: 9664.84 | AE15: =IF(AD16="","",IF(AD16=AD15,"",AD16-AD15)) -> 2.23 | AF15: =IF(J15="","",J15) -> ME | AG15: 8 | AH15: 45120.91 | AI15: =IF(AH16="","",IF(AH16=AH15,"",AH16-AH15)) -> 13.6 | AJ15: 47258.09 | AK15: =IF(AJ16="","",IF(AJ16=AJ15,"",AJ16-AJ15)) -> 8.25 | AL15: 585.26 | AM15: =IF(AL16="","",IF(AL16=AL15,"",AL16-AL15)) | AN15: 546.34 | AO15: =IF(AN16="","",IF(AN16=AN15,"",AN16-AN15)) | AP15: =IF(J15="","",J15) -> ME | AQ15: 8 | AR15: 6507.15 | AS15: =IF(AR16="","",IF(AR16=AR15,"",AR16-AR15)) | AT15: 7148.79 | AU15: =IF(AT16="","",IF(AT16=AT15,"",AT16-AT15)) -> 4.26 | AV15: 247.23 | AW15: =IF(AV16="","",IF(AV16=AV15,"",AV16-AV15)) | AX15: 235.36 | AY15: =IF(AX16="","",IF(AX16=AX15,"",AX16-AX15)) | AZ15: =IF(J15="","",J15) -> ME | BA15: 8 | BB15: 0.812 | BC15: 46 | BD15: 7.3 | BE15: 2.6 | BF15: 14.2 | BG15: 7.3 | BH15: 0.261 | BI15: 0.273 | BJ15: 0.061 | BK15: 0.062 | BL15: 0.074 | BM15: 0.068 | BN15: =IF(J15="","",J15) -> ME | BO15: 8 | BP15: 0.117 | BQ15: 0 | BR15: 7.3 | BS15: 7.3 | BT15: 18.1 | BU15: 0.015 | BV15: 1.25 | BW15: 0.99 | BX15: 0620 | BY15: 60 Livengood | BZ15: =IF(J15="","",J15) -> ME | CA15: 8 | CB15: 86.6 | CD15: =IF(CB16="","",IF(CC15="",IF(CB15=CB16,"",(CB15-CB16)),IF(CC15=CB16,"",(CC15-CB16)))) -> 1 | CE15: =IF(CD15="","",(CD15*(0.785*77*77)/1000)) -> 4.654265 | CF15: =IF(CE15="","",(CE15*0.12*1000)/I15) -> 4.1993368 | CG15: 115 | CH15: 100 | CI15: =IF(J15="","",J15) -> ME | CJ15: 8 | CK15: 85.6 | CL15: 97.1 | CM15: =IF(CK16="","",IF(CL15="",IF(CK15=CK16,"",(CK15-CK16)),IF(CL15=CK16,"",(CL15-CK16)))) -> 2.3 | CN15: =IF(CM15="","",(CM15*(0.785*77*77)/1000)) -> 10.704809 | CO15: =IF(CN15="","",(CN15*0.33*1.205*1000)/C15) -> 27.641347 | CP15: 55 | CQ15: 83 | CR15: =IF(J15="","",J15) -> ME | CS15: 8 | CT15: 102.7 | CV15: =IF(CT16="","",IF(CU15="",IF(CT15=CT16,"",(CT15-CT16)),IF(CU15=CT16,"",(CU15-CT16)))) -> 1.6 | CW15: =IF(CV15="","",(CV15*(0.785*92*92)/1000)) -> 10.630784 | CX15: =IF(CW15="","",(CW15)/C15) -> 0.069031065 | CY15: 17/17 | CZ15: 100/100 | DB15: =IF(J15="","",J15) -> ME | DC15: 8 | DD15: 91.6 | DE15: 102.9 | DF15: =IF(DD16="","",IF(DE15="",IF(DD15=DD16,"",(DD15-DD16)),IF(DE15=DD16,"",(DE15-DD16)))) -> 13.6 | DG15: =IF(DF15="","",(DF15*(0.785*92*92)*0.00812/1000)) -> 0.73373671 | DH15: =IF(DG15="","",(DG15*1000)/C15) -> 4.7645241 | DI15: 92 | DJ15: 54 | DK15: =IF(J15="","",J15) -> ME | DL15: 8 | DM15: 8.77 | DN15: 0.022 | DO15: 0.029 | DP15: 0.085 | DQ15: 6.82 | DR15: 7.3 | DS15: 1.216 | DT15: 86.5 | DU15: 4.2 | DV15: 1.185 | DW15: 0.5 | DX15: Y | DY15: =IF(J15="","",J15) -> ME | DZ15: 8 | EA15: =IF(C15="","",C15/1496) -> 0.10294118 | EB15: =IF(F15="","",IF(Q15="",F15/1360,(F15+Q15)/1360)) -> 0.11691176 | EC15: =IF(I15="","",IF(C15="","",I15/C15)) -> 0.86363636 | ED15: 1.12 | EE15: 1.23 | EF15: 0.03 | EG15: 0.05 | EH15: =IF(J15="","",J15) -> ME | EI15: 8 | EJ15: Received Bulk PACL 2448l and 1680l of cl2 (ME) | EQ15: =IF(J15="","",J15) -> ME
A16: 9 | B16: 861025 | C16: =IF(B17="","",IF(B17=B16,"",(B17-B16))) -> 252 | D16: 9.45 | E16: 765414 | F16: =IF(E17="","",IF(E17=E16,"",(E17-E16))) -> 193 | G16: 1.06 | H16: 729094 | I16: =IF(H17="","",IF(H17=H16,"",(H17-H16))) -> 180 | J16: ME | K16: 9 | L16: 67472 | M16: =IF(L17="","",IF(L17=L16,"",(L17-L16))) -> 41 | N16: 170169 | O16: =IF(N17="","",IF(N17=N16,"",(N17-N16))) -> 44 | P16: 194713 | Q16: =IF(P17="","",IF(P17=P16,"",(P17-P16))) | R16: 652 | S16: 661 | T16: 136 | U16: 133 | V16: =IF(J16="","",J16) -> ME | W16: 9 | X16: 11325.39 | Y16: =IF(X17="","",IF(X17=X16,"",X17-X16)) -> 3.5 | Z16: 12090.6 | AA16: =IF(Z17="","",IF(Z17=Z16,"",Z17-Z16)) -> 4.12 | AB16: 9572.03 | AC16: =IF(AB17="","",IF(AB17=AB16,"",AB17-AB16)) -> 1.69 | AD16: 9667.07 | AE16: =IF(AD17="","",IF(AD17=AD16,"",AD17-AD16)) -> 2.73 | AF16: =IF(J16="","",J16) -> ME | AG16: 9 | AH16: 45134.51 | AI16: =IF(AH17="","",IF(AH17=AH16,"",AH17-AH16)) -> 8.77 | AJ16: 47266.34 | AK16: =IF(AJ17="","",IF(AJ17=AJ16,"",AJ17-AJ16)) -> 15.75 | AL16: 585.26 | AM16: =IF(AL17="","",IF(AL17=AL16,"",AL17-AL16)) | AN16: 546.34 | AO16: =IF(AN17="","",IF(AN17=AN16,"",AN17-AN16)) | AP16: =IF(J16="","",J16) -> ME | AQ16: 9 | AR16: 6507.15 | AS16: =IF(AR17="","",IF(AR17=AR16,"",AR17-AR16)) | AT16: 7153.05 | AU16: =IF(AT17="","",IF(AT17=AT16,"",AT17-AT16)) -> 4.06 | AV16: 247.23 | AW16: =IF(AV17="","",IF(AV17=AV16,"",AV17-AV16)) -> 0.34 | AX16: 235.36 | AY16: =IF(AX17="","",IF(AX17=AX16,"",AX17-AX16)) | AZ16: =IF(J16="","",J16) -> ME | BA16: 9 | BB16: 0.879 | BC16: 15 | BD16: 7.3 | BE16: 2.7 | BF16: 16.2 | BG16: 7.3 | BH16: 0.372 | BI16: 0.356 | BJ16: 0.071 | BK16: 0.067 | BL16: 0.052 | BM16: 0.059 | BN16: =IF(J16="","",J16) -> ME | BO16: 9 | BP16: 0.097 | BQ16: 0 | BR16: 7.3 | BS16: 7.3 | BT16: 17.4 | BU16: 0.01 | BV16: 1.16 | BW16: 1 | BX16: 0620 | BY16: 60 Livengood | BZ16: =IF(J16="","",J16) -> ME | CA16: 9 | CB16: 85.6 | CD16: =IF(CB17="","",IF(CC16="",IF(CB16=CB17,"",(CB16-CB17)),IF(CC16=CB17,"",(CC16-CB17)))) -> 1.7 | CE16: =IF(CD16="","",(CD16*(0.785*77*77)/1000)) -> 7.9122505 | CF16: =IF(CE16="","",(CE16*0.12*1000)/I16) -> 5.2748337 | CG16: 121 | CH16: 100 | CI16: =IF(J16="","",J16) -> ME | CJ16: 9 | CK16: 94.8 | CM16: =IF(CK17="","",IF(CL16="",IF(CK16=CK17,"",(CK16-CK17)),IF(CL16=CK17,"",(CL16-CK17)))) -> 3.2 | CN16: =IF(CM16="","",(CM16*(0.785*77*77)/1000)) -> 14.893648 | CO16: =IF(CN16="","",(CN16*0.33*1.205*1000)/C16) -> 23.501822 | CP16: 53 | CQ16: 83 | CR16: =IF(J16="","",J16) -> ME | CS16: 9 | CT16: 101.1 | CV16: =IF(CT17="","",IF(CU16="",IF(CT16=CT17,"",(CT16-CT17)),IF(CU16=CT17,"",(CU16-CT17)))) -> 2.6 | CW16: =IF(CV16="","",(CV16*(0.785*92*92)/1000)) -> 17.275024 | CX16: =IF(CW16="","",(CW16)/C16) -> 0.068551683 | CY16: 16/16 | CZ16: 100/100 | DB16: =IF(J16="","",J16) -> ME | DC16: 9 | DD16: 89.3 | DE16: 103.8 | DF16: =IF(DD17="","",IF(DE16="",IF(DD16=DD17,"",(DD16-DD17)),IF(DE16=DD17,"",(DE16-DD17)))) -> 20.5 | DG16: =IF(DF16="","",(DF16*(0.785*92*92)*0.00812/1000)) -> 1.1060002 | DH16: =IF(DG16="","",(DG16*1000)/C16) -> 4.3888896 | DI16: 90 | DJ16: 54 | DK16: =IF(J16="","",J16) -> ME | DL16: 9 | DM16: 8.72 | DN16: 0.019 | DO16: 0.029 | DP16: 0.069 | DQ16: 6.82 | DR16: 7.3 | DS16: 1.149 | DT16: 86.2 | DU16: 4.2 | DV16: 0.816 | DW16: 0.448 | DX16: Y | DY16: =IF(J16="","",J16) -> ME | DZ16: 9 | EA16: =IF(C16="","",C16/1496) -> 0.1684492 | EB16: =IF(F16="","",IF(Q16="",F16/1360,(F16+Q16)/1360)) -> 0.14191176 | EC16: =IF(I16="","",IF(C16="","",I16/C16)) -> 0.71428571 | ED16: 1.1 | EE16: 1.18 | EF16: 0.03 | EG16: 0.05 | EH16: =IF(J16="","",J16) -> ME | EI16: 9 | EQ16: =IF(J16="","",J16) -> ME
A17: 10 | B17: 861277 | C17: =IF(B18="","",IF(B18=B17,"",(B18-B17))) -> 151 | D17: 9.31 | E17: 765607 | F17: =IF(E18="","",IF(E18=E17,"",(E18-E17))) -> 221 | G17: 0.47 | H17: 729274 | I17: =IF(H18="","",IF(H18=H17,"",(H18-H17))) -> 131 | J17: ME | K17: 10 | L17: 67513 | M17: =IF(L18="","",IF(L18=L17,"",(L18-L17))) | N17: 170213 | O17: =IF(N18="","",IF(N18=N17,"",(N18-N17))) -> 50 | P17: 194713 | Q17: =IF(P18="","",IF(P18=P17,"",(P18-P17))) | R17: 653 | S17: 661 | T17: 136 | U17: 133 | V17: =IF(J17="","",J17) -> ME | W17: 10 | X17: 11328.89 | Y17: =IF(X18="","",IF(X18=X17,"",X18-X17)) -> 2.21 | Z17: 12094.72 | AA17: =IF(Z18="","",IF(Z18=Z17,"",Z18-Z17)) -> 2.18 | AB17: 9573.72 | AC17: =IF(AB18="","",IF(AB18=AB17,"",AB18-AB17)) -> 1.75 | AD17: 9669.8 | AE17: =IF(AD18="","",IF(AD18=AD17,"",AD18-AD17)) -> 1.73 | AF17: =IF(J17="","",J17) -> ME | AG17: 10 | AH17: 45143.28 | AI17: =IF(AH18="","",IF(AH18=AH17,"",AH18-AH17)) -> 15.24 | AJ17: 47282.09 | AK17: =IF(AJ18="","",IF(AJ18=AJ17,"",AJ18-AJ17)) -> 12.75 | AL17: 585.26 | AM17: =IF(AL18="","",IF(AL18=AL17,"",AL18-AL17)) | AN17: 546.34 | AO17: =IF(AN18="","",IF(AN18=AN17,"",AN18-AN17)) | AP17: =IF(J17="","",J17) -> ME | AQ17: 10 | AR17: 6507.15 | AS17: =IF(AR18="","",IF(AR18=AR17,"",AR18-AR17)) | AT17: 7157.11 | AU17: =IF(AT18="","",IF(AT18=AT17,"",AT18-AT17)) -> 4.21 | AV17: 247.57 | AW17: =IF(AV18="","",IF(AV18=AV17,"",AV18-AV17)) | AX17: 235.36 | AY17: =IF(AX18="","",IF(AX18=AX17,"",AX18-AX17)) | AZ17: =IF(J17="","",J17) -> ME | BA17: 10 | BN17: =IF(J17="","",J17) -> ME | BO17: 10 | BP17: 0.082 | BV17: 1.14 | BW17: 1.07 | BX17: 0650 | BY17: 60 Livengood | BZ17: =IF(J17="","",J17) -> ME | CA17: 10 | CB17: 83.9 | CD17: =IF(CB18="","",IF(CC17="",IF(CB17=CB18,"",(CB17-CB18)),IF(CC17=CB18,"",(CC17-CB18)))) -> 0.9 | CE17: =IF(CD17="","",(CD17*(0.785*77*77)/1000)) -> 4.1888385 | CF17: =IF(CE17="","",(CE17*0.12*1000)/I17) -> 3.837104 | CG17: 121 | CH17: 100 | CI17: =IF(J17="","",J17) -> ME | CJ17: 10 | CK17: 91.6 | CM17: =IF(CK18="","",IF(CL17="",IF(CK17=CK18,"",(CK17-CK18)),IF(CL17=CK18,"",(CL17-CK18)))) -> 1.7 | CN17: =IF(CM17="","",(CM17*(0.785*77*77)/1000)) -> 7.9122505 | CO17: =IF(CN17="","",(CN17*0.33*1.205*1000)/C17) -> 20.836466 | CP17: 53 | CQ17: 83 | CR17: =IF(J17="","",J17) -> ME | CS17: 10 | CT17: 98.5 | CV17: =IF(CT18="","",IF(CU17="",IF(CT17=CT18,"",(CT17-CT18)),IF(CU17=CT18,"",(CU17-CT18)))) -> 1.6 | CW17: =IF(CV17="","",(CV17*(0.785*92*92)/1000)) -> 10.630784 | CX17: =IF(CW17="","",(CW17)/C17) -> 0.070402543 | CY17: 16/16 | CZ17: 100/100 | DB17: =IF(J17="","",J17) -> ME | DC17: 10 | DD17: 83.3 | DE17: 103.3 | DF17: =IF(DD18="","",IF(DE17="",IF(DD17=DD18,"",(DD17-DD18)),IF(DE17=DD18,"",(DE17-DD18)))) -> 13.7 | DG17: =IF(DF17="","",(DF17*(0.785*92*92)*0.00812/1000)) -> 0.73913183 | DH17: =IF(DG17="","",(DG17*1000)/C17) -> 4.8949128 | DI17: 90 | DJ17: 54 | DK17: =IF(J17="","",J17) -> ME | DL17: 10 | DM17: 8.65 | DN17: 0.022 | DO17: 0.029 | DP17: 0.058 | DQ17: 6.82 | DR17: 7.2 | DS17: 1.143 | DT17: 86.3 | DU17: 4.28 | DV17: 1.832 | DW17: 0.746 | DX17: Y | DY17: =IF(J17="","",J17) -> ME | DZ17: 10 | EA17: =IF(C17="","",C17/1496) -> 0.10093583 | EB17: =IF(F17="","",IF(Q17="",F17/1360,(F17+Q17)/1360)) -> 0.1625 | EC17: =IF(I17="","",IF(C17="","",I17/C17)) -> 0.86754967 | ED17: 1.07 | EE17: 1.15 | EF17: 0.04 | EG17: 0.07 | EH17: =IF(J17="","",J17) -> ME | EI17: 10 | EQ17: =IF(J17="","",J17) -> ME
A18: 11 | B18: 861428 | C18: =IF(B19="","",IF(B19=B18,"",(B19-B18))) -> 175 | D18: 9.66 | E18: 765828 | F18: =IF(E19="","",IF(E19=E18,"",(E19-E18))) -> 148 | G18: 1.44 | H18: 729405 | I18: =IF(H19="","",IF(H19=H18,"",(H19-H18))) -> 151 | J18: ME | K18: 11 | L18: 67513 | M18: =IF(L19="","",IF(L19=L18,"",(L19-L18))) | N18: 170263 | O18: =IF(N19="","",IF(N19=N18,"",(N19-N18))) -> 40 | P18: 194713 | Q18: =IF(P19="","",IF(P19=P18,"",(P19-P18))) | R18: 653 | S18: 661 | T18: 136 | U18: 133 | V18: =IF(J18="","",J18) -> ME | W18: 11 | X18: 11331.1 | Y18: =IF(X19="","",IF(X19=X18,"",X19-X18)) -> 3.15 | Z18: 12096.9 | AA18: =IF(Z19="","",IF(Z19=Z18,"",Z19-Z18)) -> 1.91 | AB18: 9575.47 | AC18: =IF(AB19="","",IF(AB19=AB18,"",AB19-AB18)) -> 2.55 | AD18: 9671.53 | AE18: =IF(AD19="","",IF(AD19=AD18,"",AD19-AD18)) -> 1.48 | AF18: =IF(J18="","",J18) -> ME | AG18: 11 | AH18: 45158.52 | AI18: =IF(AH19="","",IF(AH19=AH18,"",AH19-AH18)) -> 12.07 | AJ18: 47294.84 | AK18: =IF(AJ19="","",IF(AJ19=AJ18,"",AJ19-AJ18)) -> 11.26 | AL18: 585.26 | AM18: =IF(AL19="","",IF(AL19=AL18,"",AL19-AL18)) | AN18: 546.34 | AO18: =IF(AN19="","",IF(AN19=AN18,"",AN19-AN18)) | AP18: =IF(J18="","",J18) -> ME | AQ18: 11 | AR18: 6507.15 | AS18: =IF(AR19="","",IF(AR19=AR18,"",AR19-AR18)) | AT18: 7161.32 | AU18: =IF(AT19="","",IF(AT19=AT18,"",AT19-AT18)) -> 4.4 | AV18: 247.57 | AW18: =IF(AV19="","",IF(AV19=AV18,"",AV19-AV18)) | AX18: 235.36 | AY18: =IF(AX19="","",IF(AX19=AX18,"",AX19-AX18)) | AZ18: =IF(J18="","",J18) -> ME | BA18: 11 | BB18: 0.862 | BC18: 13 | BD18: 7.3 | BE18: 2.6 | BF18: 12.2 | BG18: 7.3 | BH18: 0.269 | BI18: 0.256 | BJ18: 0.055 | BK18: 0.048 | BL18: 0.054 | BM18: 0.052 | BN18: =IF(J18="","",J18) -> ME | BO18: 11 | BP18: 0.081 | BQ18: 0 | BR18: 7.3 | BS18: 7.1 | BT18: 16.9 | BU18: 0.012 | BV18: 1.1 | BW18: 1.02 | BX18: 0620 | BY18: 60 Livengood | BZ18: =IF(J18="","",J18) -> ME | CA18: 11 | CB18: 83 | CC18: 95.6 | CD18: =IF(CB19="","",IF(CC18="",IF(CB18=CB19,"",(CB18-CB19)),IF(CC18=CB19,"",(CC18-CB19)))) -> 1.7 | CE18: =IF(CD18="","",(CD18*(0.785*77*77)/1000)) -> 7.9122505 | CF18: =IF(CE18="","",(CE18*0.12*1000)/I18) -> 6.2878812 | CG18: 136 | CH18: 100 | CI18: =IF(J18="","",J18) -> ME | CJ18: 11 | CK18: 89.9 | CM18: =IF(CK19="","",IF(CL18="",IF(CK18=CK19,"",(CK18-CK19)),IF(CL18=CK19,"",(CL18-CK19)))) -> 2.1 | CN18: =IF(CM18="","",(CM18*(0.785*77*77)/1000)) -> 9.7739565 | CO18: =IF(CN18="","",(CN18*0.33*1.205*1000)/C18) -> 22.209222 | CP18: 53 | CQ18: 83 | CR18: =IF(J18="","",J18) -> ME | CS18: 11 | CT18: 96.9 | CU18: 92.5 | CV18: =IF(CT19="","",IF(CU18="",IF(CT18=CT19,"",(CT18-CT19)),IF(CU18=CT19,"",(CU18-CT19)))) -> 1.8 | CW18: =IF(CV18="","",(CV18*(0.785*92*92)/1000)) -> 11.959632 | CX18: =IF(CW18="","",(CW18)/C18) -> 0.068340754 | CY18: 16/16 | CZ18: 100/100 | DA18: Y | DB18: =IF(J18="","",J18) -> ME | DC18: 11 | DD18: 89.6 | DE18: 103.4 | DF18: =IF(DD19="","",IF(DE18="",IF(DD18=DD19,"",(DD18-DD19)),IF(DE18=DD19,"",(DE18-DD19)))) -> 12.9 | DG18: =IF(DF18="","",(DF18*(0.785*92*92)*0.00812/1000)) -> 0.69597085 | DH18: =IF(DG18="","",(DG18*1000)/C18) -> 3.9769763 | DI18: 90 | DJ18: 54 | DK18: =IF(J18="","",J18) -> ME | DL18: 11 | DM18: 7.12 | DN18: 0.024 | DO18: 0.025 | DP18: 0.057 | DQ18: 6.81 | DR18: 7.1 | DS18: 1.026 | DT18: 86.4 | DU18: 4.11 | DV18: 1.147 | DW18: 0.434 | DX18: Y | DY18: =IF(J18="","",J18) -> ME | DZ18: 11 | EA18: =IF(C18="","",C18/1496) -> 0.11697861 | EB18: =IF(F18="","",IF(Q18="",F18/1360,(F18+Q18)/1360)) -> 0.10882353 | EC18: =IF(I18="","",IF(C18="","",I18/C18)) -> 0.86285714 | ED18: 0.99 | EE18: 1.27 | EF18: 0.03 | EG18: 0.06 | EH18: =IF(J18="","",J18) -> ME | EI18: 11 | EQ18: =IF(J18="","",J18) -> ME
A19: 12 | B19: 861603 | C19: =IF(B20="","",IF(B20=B19,"",(B20-B19))) -> 135 | D19: 9.81 | E19: 765976 | F19: =IF(E20="","",IF(E20=E19,"",(E20-E19))) -> 148 | G19: 3.33 | H19: 729556 | I19: =IF(H20="","",IF(H20=H19,"",(H20-H19))) -> 115 | J19: ME | K19: 12 | L19: 67513 | M19: =IF(L20="","",IF(L20=L19,"",(L20-L19))) | N19: 170303 | O19: =IF(N20="","",IF(N20=N19,"",(N20-N19))) -> 28 | P19: 194713 | Q19: =IF(P20="","",IF(P20=P19,"",(P20-P19))) | R19: 653 | S19: 661 | T19: 136 | U19: 133 | V19: =IF(J19="","",J19) -> ME | W19: 12 | X19: 11334.25 | Y19: =IF(X20="","",IF(X20=X19,"",X20-X19)) -> 1.91 | Z19: 12098.81 | AA19: =IF(Z20="","",IF(Z20=Z19,"",Z20-Z19)) -> 2.02 | AB19: 9578.02 | AC19: =IF(AB20="","",IF(AB20=AB19,"",AB20-AB19)) -> 1.5 | AD19: 9673.01 | AE19: =IF(AD20="","",IF(AD20=AD19,"",AD20-AD19)) -> 1.56 | AF19: =IF(J19="","",J19) -> ME | AG19: 12 | AH19: 45170.59 | AI19: =IF(AH20="","",IF(AH20=AH19,"",AH20-AH19)) -> 11.94 | AJ19: 47306.1 | AK19: =IF(AJ20="","",IF(AJ20=AJ19,"",AJ20-AJ19)) -> 11.88 | AL19: 585.26 | AM19: =IF(AL20="","",IF(AL20=AL19,"",AL20-AL19)) | AN19: 546.34 | AO19: =IF(AN20="","",IF(AN20=AN19,"",AN20-AN19)) | AP19: =IF(J19="","",J19) -> ME | AQ19: 12 | AR19: 6507.15 | AS19: =IF(AR20="","",IF(AR20=AR19,"",AR20-AR19)) | AT19: 7165.72 | AU19: =IF(AT20="","",IF(AT20=AT19,"",AT20-AT19)) -> 2.97 | AV19: 247.57 | AW19: =IF(AV20="","",IF(AV20=AV19,"",AV20-AV19)) | AX19: 235.36 | AY19: =IF(AX20="","",IF(AX20=AX19,"",AX20-AX19)) | AZ19: =IF(J19="","",J19) -> ME | BA19: 12 | BB19: 0.715 | BC19: 43 | BD19: 7.3 | BE19: 2.6 | BF19: 14.2 | BG19: 7.3 | BH19: 0.319 | BI19: 0.246 | BJ19: 0.05 | BK19: 0.046 | BL19: 0.061 | BM19: 0.048 | BN19: =IF(J19="","",J19) -> ME | BO19: 12 | BP19: 0.088 | BQ19: 0 | BR19: 7.3 | BS19: 7.1 | BT19: 17.4 | BU19: 0.008 | BV19: 1.17 | BW19: 1.08 | BX19: 0620 | BY19: 60 Livengood | BZ19: =IF(J19="","",J19) -> ME | CA19: 12 | CB19: 93.9 | CD19: =IF(CB20="","",IF(CC19="",IF(CB19=CB20,"",(CB19-CB20)),IF(CC19=CB20,"",(CC19-CB20)))) -> 1.7 | CE19: =IF(CD19="","",(CD19*(0.785*77*77)/1000)) -> 7.9122505 | CF19: =IF(CE19="","",(CE19*0.12*1000)/I19) -> 8.2562614 | CG19: 128 | CH19: 100 | CI19: =IF(J19="","",J19) -> ME | CJ19: 12 | CK19: 87.8 | CM19: =IF(CK20="","",IF(CL19="",IF(CK19=CK20,"",(CK19-CK20)),IF(CL19=CK20,"",(CL19-CK20)))) -> 1.6 | CN19: =IF(CM19="","",(CM19*(0.785*77*77)/1000)) -> 7.446824 | CO19: =IF(CN19="","",(CN19*0.33*1.205*1000)/C19) -> 21.935034 | CP19: 55 | CQ19: 83 | CR19: =IF(J19="","",J19) -> ME | CS19: 12 | CT19: 90.7 | CV19: =IF(CT20="","",IF(CU19="",IF(CT19=CT20,"",(CT19-CT20)),IF(CU19=CT20,"",(CU19-CT20)))) -> 1.5 | CW19: =IF(CV19="","",(CV19*(0.785*92*92)/1000)) -> 9.96636 | CX19: =IF(CW19="","",(CW19)/C19) -> 0.073824889 | CY19: 17/17 | CZ19: 100/100 | DB19: =IF(J19="","",J19) -> ME | DC19: 12 | DD19: 90.5 | DE19: 103 | DF19: =IF(DD20="","",IF(DE19="",IF(DD19=DD20,"",(DD19-DD20)),IF(DE19=DD20,"",(DE19-DD20)))) -> 11.9 | DG19: =IF(DF19="","",(DF19*(0.785*92*92)*0.00812/1000)) -> 0.64201962 | DH19: =IF(DG19="","",(DG19*1000)/C19) -> 4.7557009 | DI19: 92 | DJ19: 54 | DK19: =IF(J19="","",J19) -> ME | DL19: 12 | DM19: 8.87 | DN19: 0.023 | DO19: 0.026 | DP19: 0.055 | DQ19: 6.82 | DR19: 7.1 | DS19: 1.147 | DT19: 85.3 | DU19: 4.21 | DV19: 0.668 | DW19: 0.486 | DX19: Y | DY19: =IF(J19="","",J19) -> ME | DZ19: 12 | EA19: =IF(C19="","",C19/1496) -> 0.090240642 | EB19: =IF(F19="","",IF(Q19="",F19/1360,(F19+Q19)/1360)) -> 0.10882353 | EC19: =IF(I19="","",IF(C19="","",I19/C19)) -> 0.85185185 | ED19: 1.04 | EE19: 1.19 | EF19: 0.03 | EG19: 0.06 | EH19: =IF(J19="","",J19) -> ME | EI19: 12 | EQ19: =IF(J19="","",J19) -> ME
A20: 13 | B20: 861738 | C20: =IF(B21="","",IF(B21=B20,"",(B21-B20))) -> 182 | D20: 9.89 | E20: 766124 | F20: =IF(E21="","",IF(E21=E20,"",(E21-E20))) -> 153 | G20: 2.83 | H20: 729671 | I20: =IF(H21="","",IF(H21=H20,"",(H21-H20))) -> 120 | J20: ME | K20: 13 | L20: 67513 | M20: =IF(L21="","",IF(L21=L20,"",(L21-L20))) -> 42 | N20: 170331 | O20: =IF(N21="","",IF(N21=N20,"",(N21-N20))) -> 45 | P20: 194713 | Q20: =IF(P21="","",IF(P21=P20,"",(P21-P20))) | R20: 653 | S20: 661 | T20: 136 | U20: 133 | V20: =IF(J20="","",J20) -> ME | W20: 13 | X20: 11336.16 | Y20: =IF(X21="","",IF(X21=X20,"",X21-X20)) -> 4.12 | Z20: 12100.83 | AA20: =IF(Z21="","",IF(Z21=Z20,"",Z21-Z20)) -> 1.33 | AB20: 9579.52 | AC20: =IF(AB21="","",IF(AB21=AB20,"",AB21-AB20)) -> 1.62 | AD20: 9674.57 | AE20: =IF(AD21="","",IF(AD21=AD20,"",AD21-AD20)) -> 1.58 | AF20: =IF(J20="","",J20) -> ME | AG20: 13 | AH20: 45182.53 | AI20: =IF(AH21="","",IF(AH21=AH20,"",AH21-AH20)) -> 11.92 | AJ20: 47317.98 | AK20: =IF(AJ21="","",IF(AJ21=AJ20,"",AJ21-AJ20)) -> 12.13 | AL20: 585.26 | AM20: =IF(AL21="","",IF(AL21=AL20,"",AL21-AL20)) | AN20: 546.34 | AO20: =IF(AN21="","",IF(AN21=AN20,"",AN21-AN20)) | AP20: =IF(J20="","",J20) -> ME | AQ20: 13 | AR20: 6507.15 | AS20: =IF(AR21="","",IF(AR21=AR20,"",AR21-AR20)) | AT20: 7168.69 | AU20: =IF(AT21="","",IF(AT21=AT20,"",AT21-AT20)) -> 3.76 | AV20: 247.57 | AW20: =IF(AV21="","",IF(AV21=AV20,"",AV21-AV20)) | AX20: 235.36 | AY20: =IF(AX21="","",IF(AX21=AX20,"",AX21-AX20)) -> 0.34 | AZ20: =IF(J20="","",J20) -> ME | BA20: 13 | BB20: 0.694 | BC20: 28 | BD20: 7.2 | BE20: 2.8 | BF20: 13.7 | BG20: 7.2 | BH20: 0.296 | BI20: 0.271 | BJ20: 0.058 | BK20: 0.057 | BL20: 0.05 | BM20: 0.049 | BN20: =IF(J20="","",J20) -> ME | BO20: 13 | BP20: 0.08 | BQ20: 0 | BR20: 7.2 | BS20: 7.2 | BT20: 17.2 | BU20: 0.01 | BV20: 1.23 | BW20: 1.1 | BX20: 0650 | BY20: 60 Livengood | BZ20: =IF(J20="","",J20) -> ME | CA20: 13 | CB20: 92.2 | CD20: =IF(CB21="","",IF(CC20="",IF(CB20=CB21,"",(CB20-CB21)),IF(CC20=CB21,"",(CC20-CB21)))) -> 1.4 | CE20: =IF(CD20="","",(CD20*(0.785*77*77)/1000)) -> 6.515971 | CF20: =IF(CE20="","",(CE20*0.12*1000)/I20) -> 6.515971 | CG20: 100 | CH20: 100 | CI20: =IF(J20="","",J20) -> ME | CJ20: 13 | CK20: 86.2 | CL20: 97.9 | CM20: =IF(CK21="","",IF(CL20="",IF(CK20=CK21,"",(CK20-CK21)),IF(CL20=CK21,"",(CL20-CK21)))) -> 2.3 | CN20: =IF(CM20="","",(CM20*(0.785*77*77)/1000)) -> 10.70481 | CO20: =IF(CN20="","",(CN20*0.33*1.205*1000)/C20) -> 23.388832 | CP20: 55 | CQ20: 83 | CR20: =IF(J20="","",J20) -> ME | CS20: 13 | CT20: 89.2 | CU20: 113.5 | CV20: =IF(CT21="","",IF(CU20="",IF(CT20=CT21,"",(CT20-CT21)),IF(CU20=CT21,"",(CU20-CT21)))) -> 1.3 | CW20: =IF(CV20="","",(CV20*(0.785*92*92)/1000)) -> 8.637512 | CX20: =IF(CW20="","",(CW20)/C20) -> 0.047458857 | CY20: 17/17 | CZ20: 100/100 | DB20: =IF(J20="","",J20) -> ME | DC20: 13 | DD20: 91.1 | DE20: 106.9 | DF20: =IF(DD21="","",IF(DE20="",IF(DD20=DD21,"",(DD20-DD21)),IF(DE20=DD21,"",(DE20-DD21)))) -> 17.6 | DG20: =IF(DF20="","",(DF20*(0.785*92*92)*0.00812/1000)) -> 0.94954163 | DH20: =IF(DG20="","",(DG20*1000)/C20) -> 5.2172617 | DI20: 93 | DJ20: 54 | DK20: =IF(J20="","",J20) -> ME | DL20: 13 | DM20: 8.67 | DN20: 0.023 | DO20: 0.026 | DP20: 0.054 | DQ20: 6.84 | DR20: 7.2 | DS20: 1.207 | DT20: 83.5 | DU20: 4.2 | DV20: 0.686 | DW20: 0.658 | DX20: N | DY20: =IF(J20="","",J20) -> ME | DZ20: 13 | EA20: =IF(C20="","",C20/1496) -> 0.12165775 | EB20: =IF(F20="","",IF(Q20="",F20/1360,(F20+Q20)/1360)) -> 0.1125 | EC20: =IF(I20="","",IF(C20="","",I20/C20)) -> 0.65934066 | ED20: 1.16 | EE20: 1.26 | EF20: 0.03 | EG20: 0.07 | EH20: =IF(J20="","",J20) -> ME | EI20: 13 | EJ20: change length of stroke on chemical pumps to match dosage rates (ME) | EQ20: =IF(J20="","",J20) -> ME
A21: 14 | B21: 861920 | C21: =IF(B22="","",IF(B22=B21,"",(B22-B21))) -> 141 | D21: 8.82 | E21: 766277 | F21: =IF(E22="","",IF(E22=E21,"",(E22-E21))) -> 136 | G21: 3.54 | H21: 729791 | I21: =IF(H22="","",IF(H22=H21,"",(H22-H21))) -> 119 | J21: ME | K21: 14 | L21: 67555 | M21: =IF(L22="","",IF(L22=L21,"",(L22-L21))) | N21: 170376 | O21: =IF(N22="","",IF(N22=N21,"",(N22-N21))) -> 40 | P21: 194713 | Q21: =IF(P22="","",IF(P22=P21,"",(P22-P21))) | R21: 653 | S21: 662 | T21: 136 | U21: 133 | V21: =IF(J21="","",J21) -> ME | W21: 14 | X21: 11340.28 | Y21: =IF(X22="","",IF(X22=X21,"",X22-X21)) -> 1.96 | Z21: 12102.16 | AA21: =IF(Z22="","",IF(Z22=Z21,"",Z22-Z21)) -> 2.14 | AB21: 9581.14 | AC21: =IF(AB22="","",IF(AB22=AB21,"",AB22-AB21)) -> 1.65 | AD21: 9676.15 | AE21: =IF(AD22="","",IF(AD22=AD21,"",AD22-AD21)) -> 1.53 | AF21: =IF(J21="","",J21) -> ME | AG21: 14 | AH21: 45194.45 | AI21: =IF(AH22="","",IF(AH22=AH21,"",AH22-AH21)) -> 12.08 | AJ21: 47330.11 | AK21: =IF(AJ22="","",IF(AJ22=AJ21,"",AJ22-AJ21)) -> 10.07 | AL21: 585.26 | AM21: =IF(AL22="","",IF(AL22=AL21,"",AL22-AL21)) | AN21: 546.34 | AO21: =IF(AN22="","",IF(AN22=AN21,"",AN22-AN21)) | AP21: =IF(J21="","",J21) -> ME | AQ21: 14 | AR21: 6507.15 | AS21: =IF(AR22="","",IF(AR22=AR21,"",AR22-AR21)) | AT21: 7172.45 | AU21: =IF(AT22="","",IF(AT22=AT21,"",AT22-AT21)) -> 3.7 | AV21: 247.57 | AW21: =IF(AV22="","",IF(AV22=AV21,"",AV22-AV21)) | AX21: 235.7 | AY21: =IF(AX22="","",IF(AX22=AX21,"",AX22-AX21)) | AZ21: =IF(J21="","",J21) -> ME | BA21: 14 | BB21: 0.698 | BC21: 25 | BD21: 7.3 | BE21: 2.8 | BF21: 15.8 | BG21: 7.3 | BH21: 0.232 | BI21: 0.217 | BJ21: 0.06 | BK21: 0.053 | BL21: 0.052 | BM21: 0.051 | BN21: =IF(J21="","",J21) -> ME | BO21: 14 | BP21: 0.08 | BQ21: 0 | BR21: 7.3 | BS21: 7.2 | BT21: 17.8 | BU21: 0.013 | BV21: 1.27 | BW21: 1.01 | BX21: 0550 | BY21: 60 Livengood | BZ21: =IF(J21="","",J21) -> ME | CA21: 14 | CB21: 90.8 | CD21: =IF(CB22="","",IF(CC21="",IF(CB21=CB22,"",(CB21-CB22)),IF(CC21=CB22,"",(CC21-CB22)))) -> 1.3 | CE21: =IF(CD21="","",(CD21*(0.785*77*77)/1000)) -> 6.0505445 | CF21: =IF(CE21="","",(CE21*0.12*1000)/I21) -> 6.1013894 | CG21: 76 | CH21: 100 | CI21: =IF(J21="","",J21) -> ME | CJ21: 14 | CK21: 95.6 | CM21: =IF(CK22="","",IF(CL21="",IF(CK21=CK22,"",(CK21-CK22)),IF(CL21=CK22,"",(CL21-CK22)))) -> 1.7 | CN21: =IF(CM21="","",(CM21*(0.785*77*77)/1000)) -> 7.9122505 | CO21: =IF(CN21="","",(CN21*0.33*1.205*1000)/C21) -> 22.31423 | CP21: 48 | CQ21: 83 | CR21: =IF(J21="","",J21) -> ME | CS21: 14 | CT21: 112.2 | CV21: =IF(CT22="","",IF(CU21="",IF(CT21=CT22,"",(CT21-CT22)),IF(CU21=CT22,"",(CU21-CT22)))) -> 1.4 | CW21: =IF(CV21="","",(CV21*(0.785*92*92)/1000)) -> 9.301936 | CX21: =IF(CW21="","",(CW21)/C21) -> 0.065971177 | CY21: 15/15 | CZ21: 100/100 | DB21: =IF(J21="","",J21) -> ME | DC21: 14 | DD21: 89.3 | DE21: 102.8 | DF21: =IF(DD22="","",IF(DE21="",IF(DD21=DD22,"",(DD21-DD22)),IF(DE21=DD22,"",(DE21-DD22)))) -> 13.8 | DG21: =IF(DF21="","",(DF21*(0.785*92*92)*0.00812/1000)) -> 0.74452696 | DH21: =IF(DG21="","",(DG21*1000)/C21) -> 5.280333 | DI21: 82 | DJ21: 54 | DK21: =IF(J21="","",J21) -> ME | DL21: 14 | DM21: 9.02 | DN21: 0.022 | DO21: 0.029 | DP21: 0.054 | DQ21: 6.84 | DR21: 7.2 | DS21: 1.266 | DT21: 85.9 | DU21: 4.2 | DV21: 1.495 | DW21: 0.258 | DX21: Y | DY21: =IF(J21="","",J21) -> ME | DZ21: 14 | EA21: =IF(C21="","",C21/1496) -> 0.094251337 | EB21: =IF(F21="","",IF(Q21="",F21/1360,(F21+Q21)/1360)) -> 0.1 | EC21: =IF(I21="","",IF(C21="","",I21/C21)) -> 0.84397163 | ED21: 1.23 | EE21: 1.28 | EF21: 0.03 | EG21: 0.05 | EH21: =IF(J21="","",J21) -> ME | EI21: 14 | EQ21: =IF(J21="","",J21) -> ME
A22: 15 | B22: 862061 | C22: =IF(B23="","",IF(B23=B22,"",(B23-B22))) -> 212 | D22: 9.4 | E22: 766413 | F22: =IF(E23="","",IF(E23=E22,"",(E23-E22))) -> 183 | G22: 0.63 | H22: 729910 | I22: =IF(H23="","",IF(H23=H22,"",(H23-H22))) -> 184 | J22: SA/ME | K22: 15 | L22: 67555 | M22: =IF(L23="","",IF(L23=L22,"",(L23-L22))) | N22: 170416 | O22: =IF(N23="","",IF(N23=N22,"",(N23-N22))) -> 44 | P22: 194713 | Q22: =IF(P23="","",IF(P23=P22,"",(P23-P22))) | R22: 653 | S22: 662 | T22: 136 | U22: 133 | V22: =IF(J22="","",J22) -> SA/ME | W22: 15 | X22: 11342.24 | Y22: =IF(X23="","",IF(X23=X22,"",X23-X22)) -> 2.03 | Z22: 12104.3 | AA22: =IF(Z23="","",IF(Z23=Z22,"",Z23-Z22)) -> 3.95 | AB22: 9582.79 | AC22: =IF(AB23="","",IF(AB23=AB22,"",AB23-AB22)) -> 3.32 | AD22: 9677.68 | AE22: =IF(AD23="","",IF(AD23=AD22,"",AD23-AD22)) -> 1.58 | AF22: =IF(J22="","",J22) -> SA/ME | AG22: 15 | AH22: 45206.53 | AI22: =IF(AH23="","",IF(AH23=AH22,"",AH23-AH22)) -> 13.91 | AJ22: 47340.18 | AK22: =IF(AJ23="","",IF(AJ23=AJ22,"",AJ23-AJ22)) -> 13.93 | AL22: 585.26 | AM22: =IF(AL23="","",IF(AL23=AL22,"",AL23-AL22)) | AN22: 546.34 | AO22: =IF(AN23="","",IF(AN23=AN22,"",AN23-AN22)) | AP22: =IF(J22="","",J22) -> SA/ME | AQ22: 15 | AR22: 6507.15 | AS22: =IF(AR23="","",IF(AR23=AR22,"",AR23-AR22)) | AT22: 7176.15 | AU22: =IF(AT23="","",IF(AT23=AT22,"",AT23-AT22)) -> 5.07 | AV22: 247.57 | AW22: =IF(AV23="","",IF(AV23=AV22,"",AV23-AV22)) | AX22: 235.7 | AY22: =IF(AX23="","",IF(AX23=AX22,"",AX23-AX22)) | AZ22: =IF(J22="","",J22) -> SA/ME | BA22: 15 | BB22: 0.699 | BC22: 10 | BD22: 7.3 | BE22: 2.7 | BF22: 15.6 | BG22: 7.3 | BH22: 0.322 | BI22: 0.309 | BJ22: 0.066 | BK22: 0.067 | BL22: 0.049 | BM22: 0.055 | BN22: =IF(J22="","",J22) -> SA/ME | BO22: 15 | BP22: 0.076 | BQ22: 0 | BR22: 7.3 | BS22: 7.2 | BT22: 18.2 | BU22: 0.01 | BV22: 1.24 | BW22: 1.14 | BX22: 0750 | BY22: 60 Livengood | BZ22: =IF(J22="","",J22) -> SA/ME | CA22: 15 | CB22: 89.5 | CD22: =IF(CB23="","",IF(CC22="",IF(CB22=CB23,"",(CB22-CB23)),IF(CC22=CB23,"",(CC22-CB23)))) -> 1.4 | CE22: =IF(CD22="","",(CD22*(0.785*77*77)/1000)) -> 6.515971 | CF22: =IF(CE22="","",(CE22*0.12*1000)/I22) -> 4.2495463 | CG22: 76 | CH22: 100 | CI22: =IF(J22="","",J22) -> SA/ME | CJ22: 15 | CK22: 93.9 | CM22: =IF(CK23="","",IF(CL22="",IF(CK22=CK23,"",(CK22-CK23)),IF(CL22=CK23,"",(CL22-CK23)))) -> 2.6 | CN22: =IF(CM22="","",(CM22*(0.785*77*77)/1000)) -> 12.101089 | CO22: =IF(CN22="","",(CN22*0.33*1.205*1000)/C22) -> 22.698104 | CP22: 48 | CQ22: 83 | CR22: =IF(J22="","",J22) -> SA/ME | CS22: 15 | CT22: 110.8 | CV22: =IF(CT23="","",IF(CU22="",IF(CT22=CT23,"",(CT22-CT23)),IF(CU22=CT23,"",(CU22-CT23)))) -> 2.2 | CW22: =IF(CV22="","",(CV22*(0.785*92*92)/1000)) -> 14.617328 | CX22: =IF(CW22="","",(CW22)/C22) -> 0.06894966 | CY22: 15/15 | CZ22: 100/100 | DB22: =IF(J22="","",J22) -> SA/ME | DC22: 15 | DD22: 89 | DE22: 104.9 | DF22: =IF(DD23="","",IF(DE22="",IF(DD22=DD23,"",(DD22-DD23)),IF(DE22=DD23,"",(DE22-DD23)))) -> 13.1 | DG22: =IF(DF22="","",(DF22*(0.785*92*92)*0.00812/1000)) -> 0.7067611 | DH22: =IF(DG22="","",(DG22*1000)/C22) -> 3.3337788 | DI22: 82 | DJ22: 54 | DK22: =IF(J22="","",J22) -> SA/ME | DL22: 15 | DM22: 8.59 | DN22: 0.022 | DO22: 0.028 | DP22: 0.054 | DQ22: 6.85 | DR22: 7.2 | DS22: 1.261 | DT22: 85.2 | DU22: 4.24 | DV22: 1.052 | DW22: 0.22 | DX22: Y | DY22: =IF(J22="","",J22) -> SA/ME | DZ22: 15 | EA22: =IF(C22="","",C22/1496) -> 0.14171123 | EB22: =IF(F22="","",IF(Q22="",F22/1360,(F22+Q22)/1360)) -> 0.13455882 | EC22: =IF(I22="","",IF(C22="","",I22/C22)) -> 0.86792453 | ED22: 1.23 | EE22: 1.26 | EF22: 0.03 | EG22: 0.04 | EH22: =IF(J22="","",J22) -> SA/ME | EI22: 15 | EQ22: =IF(J22="","",J22) -> SA/ME
